Workbook

Sheet compressor readings
A1: Date | B1: Time | C1: Compressor | D1: Load time | E1: Unload time | F1: Run time | G1: Stop time | H1: Fault time | I1: load% | J1: unload% | K1: Availabilty% | L1: Fault% | M1: efficency remark | N1: Cummulative load | O1: Cummulative unload | P1: cumulative run | Q1: Cumulative stop | R1: Cumulative Fault
A2: 01.06.2026 | B2: 0.41666667 | C2: C1 | D2: =N3-N2 -> 23.85 | E2: =O3-O2 -> 0.13 | F2: =P3-P2 -> 23.98 | G2: =+Q3-Q2 -> 0 | I2: =(D2/F2)*100 -> 99.457882 | J2: =(E2/F2)*100 -> 0.54211843 | K2: =(F2/(F2+G2+H2)*100) -> 100 | L2: =(H2/(F2+G2+H2))*100 -> 0 | M2: =IF(J2>40,"High Unload Loss","Efficient") -> Efficient | N2: 30634.5 | O2: 27173.13 | P2: 57808.04 | Q2: 3027.05 | R2: 353.07
A3: 02.06.2026 | B3: 0.41666667 | C3: C1 | D3: =N4-N3 -> 23.21 | E3: =O4-O3 -> 0.13 | F3: =P4-P3 -> 23.36 | G3: =+Q4-Q3 -> 0 | H3: =R4-R3 -> 0 | I3: =(D3/F3)*100 -> 99.357877 | J3: =(E3/F3)*100 -> 0.55650685 | K3: =(F3/(F3+G3+H3)*100) -> 100 | L3: =(H3/(F3+G3+H3))*100 -> 0 | M3: =IF(J3>40,"High Unload Loss","Efficient") -> Efficient | N3: 30658.35 | O3: 27173.26 | P3: 57832.02 | Q3: 3027.05 | R3: 353.07
A4: 03.06.2026 | B4: 0.41666667 | C4: C1 | D4: =N5-N4 -> 22.54 | E4: =O5-O4 -> 0.09 | F4: =P5-P4 -> 23.2 | G4: =+Q5-Q4 -> 0 | H4: =R5-R4 -> 0 | I4: =(D4/F4)*100 -> 97.155172 | J4: =(E4/F4)*100 -> 0.38793103 | K4: =(F4/(F4+G4+H4)*100) -> 100 | L4: =(H4/(F4+G4+H4))*100 -> 0 | M4: =IF(J4>40,"High Unload Loss","Efficient") -> Efficient | N4: 30681.56 | O4: 27173.39 | P4: 57855.38 | Q4: 3027.05 | R4: 353.07
A5: 04.06.2026 | B5: 0.41666667 | C5: C1 | D5: =N6-N5 -> 19.35 | E5: =O6-O5 -> 0.08 | F5: =P6-P5 -> 19.83 | G5: =+Q6-Q5 -> 0 | H5: =R6-R5 -> 0 | I5: =(D5/F5)*100 -> 97.579425 | J5: =(E5/F5)*100 -> 0.40342915 | K5: =(F5/(F5+G5+H5)*100) -> 100 | L5: =(H5/(F5+G5+H5))*100 -> 0 | M5: =IF(J5>40,"High Unload Loss","Efficient") -> Efficient | N5: 30704.1 | O5: 27173.48 | P5: 57878.58 | Q5: 3027.05 | R5: 353.07
A6: 05.06.2026 | B6: 0.41666667 | C6: C1 | D6: =N7-N6 -> -30723.45 | E6: =O7-O6 -> -27173.56 | F6: =P7-P6 -> -57898.41 | G6: =+Q7-Q6 -> -3027.05 | H6: =R7-R6 -> -353.07 | I6: =(D6/F6)*100 -> 53.064411 | J6: =(E6/F6)*100 -> 46.933171 | K6: =(F6/(F6+G6+H6)*100) -> 94.484006 | L6: =(H6/(F6+G6+H6))*100 -> 0.57617244 | M6: =IF(J6>40,"High Unload Loss","Efficient") -> High Unload Loss | N6: 30723.45 | O6: 27173.56 | P6: 57898.41 | Q6: 3027.05 | R6: 353.07
A7: 06.06.2026 | B7: 0.41666667
A8: 07.06.2026 | B8: 0.41666667
A9: 08.06.2026 | B9: 0.41666667 | C9: C1 | D9: =N10-N9 -> 20.15 | E9: =O10-O9 -> 0.92 | F9: =P10-P9 -> 21.47 | G9: =+Q10-Q9 -> 0 | H9: =R10-R9 -> 0 | I9: =(D9/F9)*100 -> 93.851886 | J9: =(E9/F9)*100 -> 4.2850489 | K9: =(F9/(F9+G9+H9)*100) -> 100 | L9: =(H9/(F9+G9+H9))*100 -> 0 | M9: =IF(J9>40,"High Unload Loss","Efficient") -> Efficient | N9: 30769.44 | O9: 27174.11 | P9: 57943.55 | Q9: 3051.55 | R9: 353.07
A10: 09.06.2026 | B10: 0.41666667 | C10: C1 | D10: =N11-N10 -> 19.96 | E10: =O11-O10 -> 1.2 | F10: =P11-P10 -> 21.16 | G10: =+Q11-Q10 -> 0 | H10: =R11-R10 -> 0 | I10: =(D10/F10)*100 -> 94.328922 | J10: =(E10/F10)*100 -> 5.6710775 | K10: =(F10/(F10+G10+H10)*100) -> 100 | L10: =(H10/(F10+G10+H10))*100 -> 0 | M10: =IF(J10>40,"High Unload Loss","Efficient") -> Efficient | N10: 30789.59 | O10: 27175.03 | P10: 57965.02 | Q10: 3051.55 | R10: 353.07
A11: 10.06.2026 | B11: 0.41666667 | C11: C1 | D11: =N12-N11 -> 21.46 | E11: =O12-O11 -> 0.779 | F11: =P12-P11 -> 21.92 | G11: =+Q12-Q11 -> 0 | H11: =R12-R11 -> 0 | I11: =(D11/F11)*100 -> 97.90146 | J11: =(E11/F11)*100 -> 3.5538321 | K11: =(F11/(F11+G11+H11)*100) -> 100 | L11: =(H11/(F11+G11+H11))*100 -> 0 | M11: =IF(J11>40,"High Unload Loss","Efficient") -> Efficient | N11: 30809.55 | O11: 27176.23 | P11: 57986.18 | Q11: 3051.55 | R11: 353.07
A12: 11.06.2026 | B12: 0.41666667 | C12: C1 | D12: =N13-N12 -> 20.3 | E12: =O13-O12 -> 1.231 | F12: =P13-P12 -> 21.45 | G12: =+Q13-Q12 -> 0 | H12: =R13-R12 -> 0 | I12: =(D12/F12)*100 -> 94.638695 | J12: =(E12/F12)*100 -> 5.7389277 | K12: =(F12/(F12+G12+H12)*100) -> 100 | L12: =(H12/(F12+G12+H12))*100 -> 0 | M12: =IF(J12>40,"High Unload Loss","Efficient") -> Efficient | N12: 30831.01 | O12: 27177.009 | P12: 58008.1 | Q12: 3051.55 | R12: 353.07
A13: 12.06.2026 | B13: 0.41666667 | C13: C1 | D13: =N14-N13 -> -30851.31 | E13: =O14-O13 -> -27178.24 | F13: =P14-P13 -> -58029.55 | G13: =+Q14-Q13 -> -3051.55 | H13: =R14-R13 -> -353.07 | I13: =(D13/F13)*100 -> 53.164827 | J13: =(E13/F13)*100 -> 46.835173 | K13: =(F13/(F13+G13+H13)*100) -> 94.4581 | L13: =(H13/(F13+G13+H13))*100 -> 0.57471274 | M13: =IF(J13>40,"High Unload Loss","Efficient") -> High Unload Loss | N13: 30851.31 | O13: 27178.24 | P13: 58029.55 | Q13: 3051.55 | R13: 353.07
A14: 13.06.2026
A15: 14.06.2026
A16: 15.06.2026 | B16: 10.00.00 | C16: C1 | D16: =N17-N16 -> 19.26 | E16: =O17-O16 -> 1.36 | F16: =P17-P16 -> 20.82 | G16: =+Q17-Q16 -> 0 | H16: =R17-R16 -> 0 | I16: =(D16/F16)*100 -> 92.507205 | J16: =(E16/F16)*100 -> 6.5321806 | K16: =(F16/(F16+G16+H16)*100) -> 100 | L16: =(H16/(F16+G16+H16))*100 -> 0 | M16: =IF(J16>40,"High Unload Loss","Efficient") -> Efficient | N16: 30892 | O16: 27181.09 | P16: 58073.29 | Q16: 3067.03 | R16: 353.07
A17: 16.06.2026 | B17: 10.00.00 | C17: C1 | D17: =N18-N17 -> 20.01 | E17: =O18-O17 -> 1.63 | F17: =P18-P17 -> 21.24 | G17: =+Q18-Q17 -> 0 | H17: =R18-R17 -> 0 | I17: =(D17/F17)*100 -> 94.20904 | J17: =(E17/F17)*100 -> 7.6741996 | K17: =(F17/(F17+G17+H17)*100) -> 100 | L17: =(H17/(F17+G17+H17))*100 -> 0 | M17: =IF(J17>40,"High Unload Loss","Efficient") -> Efficient | N17: 30911.26 | O17: 27182.45 | P17: 58094.11 | Q17: 3067.03 | R17: 353.07
A18: 17.06.2026 | B18: 10.00.00 | C18: C1 | D18: =N19-N18 -> 19.78 | E18: =O19-O18 -> 1.11 | F18: =P19-P18 -> 20.89 | G18: =+Q19-Q18 -> 0 | H18: =R19-R18 -> 0 | I18: =(D18/F18)*100 -> 94.686453 | J18: =(E18/F18)*100 -> 5.3135472 | K18: =(F18/(F18+G18+H18)*100) -> 100 | L18: =(H18/(F18+G18+H18))*100 -> 0 | M18: =IF(J18>40,"High Unload Loss","Efficient") -> Efficient | N18: 30931.27 | O18: 27184.08 | P18: 58115.35 | Q18: 3067.03 | R18: 353.07
A19: 18.06.2026 | B19: 10.00.00 | C19: C1 | D19: =N20-N19 -> 20.24 | E19: =O20-O19 -> 1 | F19: =P20-P19 -> 21.24 | G19: =+Q20-Q19 -> -10 | H19: =R20-R19 -> 0 | I19: =(D19/F19)*100 -> 95.291902 | J19: =(E19/F19)*100 -> 4.7080979 | K19: =(F19/(F19+G19+H19)*100) -> 188.96797 | L19: =(H19/(F19+G19+H19))*100 -> 0 | M19: =IF(J19>40,"High Unload Loss","Efficient") -> Efficient | N19: 30951.05 | O19: 27185.19 | P19: 58136.24 | Q19: 3067.03 | R19: 353.07
A20: 19.06.2026 | B20: 10.00.00 | C20: C1 | D20: =N21-N20 -> -30971.29 | E20: =O21-O20 -> -27186.19 | F20: =P21-P20 -> -58157.48 | G20: =+Q21-Q20 -> -3057.03 | H20: =R21-R20 -> -353.07 | I20: =(D20/F20)*100 -> 53.254182 | J20: =(E20/F20)*100 -> 46.745818 | K20: =(F20/(F20+G20+H20)*100) -> 94.461208 | L20: =(H20/(F20+G20+H20))*100 -> 0.5734674 | M20: =IF(J20>40,"High Unload Loss","Efficient") -> High Unload Loss | N20: 30971.29 | O20: 27186.19 | P20: 58157.48 | Q20: 3057.03 | R20: 353.07
A21: 20.06.2026
A22: 21.06.2026
A23: 22.06.2026 | B23: 10.00.00 | C23: C1 | D23: =N24-N23 -> -31015.38 | E23: =O24-O23 -> -2719.2 | F23: =P24-P23 -> -58207.58 | G23: =+Q24-Q23 -> -3067.03 | H23: =R24-R23 -> -353.07 | I23: =(D23/F23)*100 -> 53.284091 | J23: =(E23/F23)*100 -> 4.6715565 | K23: =(F23/(F23+G23+H23)*100) -> 94.450383 | L23: =(H23/(F23+G23+H23))*100 -> 0.57290815 | M23: =IF(J23>40,"High Unload Loss","Efficient") -> Efficient | N23: 31015.38 | O23: 2719.2 | P23: 58207.58 | Q23: 3067.03 | R23: 353.07
B31: Time | C31: Compressor | D31: Load time | E31: Unload time | F31: Run time | G31: Stop time | H31: Fault time | I31: load% | J31: unload% | K31: Availabilty% | L31: Fault% | M31: efficency remark | N31: Cummulative load | O31: Cummulative unload | P31: cumulative run | Q31: Cumulative stop | R31: Cumulative Fault
A32: =A2 -> 01.06.2026 | B32: =B2 -> 0.41666667 | C32: C2 | D32: =N33-N32 -> 18.96 | E32: =O33-O32 -> 2.11 | F32: =P33-P32 -> 21.08 | G32: =+Q33-Q32 -> 1.34 | H32: =R33-R32 -> 0 | I32: =(D32/F32)*100 -> 89.943074 | J32: =(E32/F32)*100 -> 10.009488 | K32: =(F32/(F32+G32+H32)*100) -> 94.023194 | L32: =(H32/(F32+G32+H32))*100 -> 0 | M32: =IF(J32>40,"High Unload Loss","Efficient") -> Efficient | N32: 14147.26 | O32: 7429.22 | P32: 21576.48 | Q32: 2031.03 | R32: 188.49
A33: =A3 -> 02.06.2026 | B33: =B3 -> 0.41666667 | C33: C2 | D33: =N34-N33 -> 14.94 | E33: =O34-O33 -> 1.71 | F33: =P34-P33 -> 22.65 | G33: =+Q34-Q33 -> 0.16 | H33: =R34-R33 -> 0 | I33: =(D33/F33)*100 -> 65.960265 | J33: =(E33/F33)*100 -> 7.5496689 | K33: =(F33/(F33+G33+H33)*100) -> 99.298553 | L33: =(H33/(F33+G33+H33))*100 -> 0 | M33: =IF(J33>40,"High Unload Loss","Efficient") -> Efficient | N33: 14166.22 | O33: 7431.33 | P33: 21597.56 | Q33: 2032.37 | R33: 188.49
A34: 03.06.26 | B34: 10.00AM | C34: C2 | D34: =N35-N34 -> 26.84 | E34: =O35-O34 -> 1.5 | F34: =P35-P34 -> 22.34 | G34: =+Q35-Q34 -> 0 | H34: =R35-R34 -> 0 | I34: =(D34/F34)*100 -> 120.14324 | J34: =(E34/F34)*100 -> 6.7144136 | K34: =(F34/(F34+G34+H34)*100) -> 100 | L34: =(H34/(F34+G34+H34))*100 -> 0 | M34: =IF(J34>40,"High Unload Loss","Efficient") -> Efficient | N34: 14181.16 | O34: 7433.04 | P34: 21620.21 | Q34: 2032.53 | R34: 188.49
A35: 04.06.2026 | B35: 10.00AM | C35: C2 | D35: =N36-N35 -> 17.08 | E35: =O36-O35 -> 1.82 | F35: =P36-P35 -> 18.9 | G35: =+Q36-Q35 -> 0.7 | H35: =R36-R35 -> 0 | I35: =(D35/F35)*100 -> 90.37037 | J35: =(E35/F35)*100 -> 9.6296296 | K35: =(F35/(F35+G35+H35)*100) -> 96.428571 | L35: =(H35/(F35+G35+H35))*100 -> 0 | M35: =IF(J35>40,"High Unload Loss","Efficient") -> Efficient | N35: 14208 | O35: 7434.54 | P35: 21642.55 | Q35: 2032.53 | R35: 188.49
A36: =A6 -> 05.06.2026 | B36: 10.00AM | C36: C2 | D36: =N37-N36 -> -14225.08 | E36: =O37-O36 -> -7436.36 | F36: =P37-P36 -> -21661.45 | G36: =+Q37-Q36 -> -2033.23 | H36: =R37-R36 -> -188.49 | I36: =(D36/F36)*100 -> 65.670027 | J36: =(E36/F36)*100 -> 34.329927 | K36: =(F36/(F36+G36+H36)*100) -> 90.69755 | L36: =(H36/(F36+G36+H36))*100 -> 0.78921684 | M36: =IF(J36>40,"High Unload Loss","Efficient") -> Efficient | N36: 14225.08 | O36: 7436.36 | P36: 21661.45 | Q36: 2033.23 | R36: 188.49
A37: =A7 -> 06.06.2026 | B37: 10.00AM
A38: =A8 -> 07.06.2026 | B38: 10.00AM
A39: =A9 -> 08.06.2026 | B39: 10.00AM | C39: C2 | D39: =N40-N39 -> 17.86 | E39: =O40-O39 -> 3.31 | F39: =P40-P39 -> 21.6 | G39: =+Q40-Q39 -> 0 | H39: =R40-R39 -> 0 | I39: =(D39/F39)*100 -> 82.685185 | J39: =(E39/F39)*100 -> 15.324074 | K39: =(F39/(F39+G39+H39)*100) -> 100 | L39: =(H39/(F39+G39+H39))*100 -> 0 | M39: =IF(J39>40,"High Unload Loss","Efficient") -> Efficient | N39: 14268.41 | O39: 7439.19 | P39: 21707.59 | Q39: 2056.59 | R39: 188.49
A40: =A10 -> 09.06.2026 | B40: 10.00AM | C40: C2 | D40: =N41-N40 -> 18.32 | E40: =O41-O40 -> 4.52 | F40: =P41-P40 -> 22.82 | G40: =+Q41-Q40 -> 0 | H40: =R41-R40 -> 0 | I40: =(D40/F40)*100 -> 80.280456 | J40: =(E40/F40)*100 -> 19.807187 | K40: =(F40/(F40+G40+H40)*100) -> 100 | L40: =(H40/(F40+G40+H40))*100 -> 0 | M40: =IF(J40>40,"High Unload Loss","Efficient") -> Efficient | N40: 14286.27 | O40: 7442.5 | P40: 21729.19 | Q40: 2056.59 | R40: 188.49
A41: =A11 -> 10.06.2026 | B41: 10.00AM | C41: C2 | D41: =N42-N41 -> 17.97 | E41: =O42-O41 -> 3.51 | F41: =P42-P41 -> 21.48 | G41: =+Q42-Q41 -> 0 | H41: =R42-R41 -> 0 | I41: =(D41/F41)*100 -> 83.659218 | J41: =(E41/F41)*100 -> 16.340782 | K41: =(F41/(F41+G41+H41)*100) -> 100 | L41: =(H41/(F41+G41+H41))*100 -> 0 | M41: =IF(J41>40,"High Unload Loss","Efficient") -> Efficient | N41: 14304.59 | O41: 7447.02 | P41: 21752.01 | Q41: 2056.59 | R41: 188.49
A42: =A12 -> 11.06.2026 | B42: 10.00AM | C42: C2 | D42: =N43-N42 -> 18.99 | E42: =O43-O42 -> 4.57 | F42: =P43-P42 -> 23.56 | G42: =+Q43-Q42 -> 0 | H42: =R43-R42 -> 0 | I42: =(D42/F42)*100 -> 80.602716 | J42: =(E42/F42)*100 -> 19.397284 | K42: =(F42/(F42+G42+H42)*100) -> 100 | L42: =(H42/(F42+G42+H42))*100 -> 0 | M42: =IF(J42>40,"High Unload Loss","Efficient") -> Efficient | N42: 14322.56 | O42: 7450.53 | P42: 21773.49 | Q42: 2056.59 | R42: 188.49
A43: =A13 -> 12.06.2026 | B43: 10.00AM | C43: C2 | D43: =N44-N43 -> -14341.55 | E43: =O44-O43 -> -7455.1 | F43: =P44-P43 -> -21797.05 | G43: =+Q44-Q43 -> -2056.59 | H43: =R44-R43 -> -188.49 | I43: =(D43/F43)*100 -> 65.79583 | J43: =(E43/F43)*100 -> 34.202335 | K43: =(F43/(F43+G43+H43)*100) -> 90.661892 | L43: =(H43/(F43+G43+H43))*100 -> 0.78399876 | M43: =IF(J43>40,"High Unload Loss","Efficient") -> Efficient | N43: 14341.55 | O43: 7455.1 | P43: 21797.05 | Q43: 2056.59 | R43: 188.49
A44: =A14 -> 13.06.2026
A45: =A15 -> 14.06.2026
A46: =A16 -> 15.06.2026 | B46: 10.00AM | C46: C2 | D46: =N47-N46 -> 18.17 | E46: =O47-O46 -> 4.84 | F46: =P47-P46 -> 523.02 | G46: =+Q47-Q46 -> 0 | H46: =R47-R46 -> 0 | I46: =(D46/F46)*100 -> 3.4740545 | J46: =(E46/F46)*100 -> 0.92539482 | K46: =(F46/(F46+G46+H46)*100) -> 100 | L46: =(H46/(F46+G46+H46))*100 -> 0 | M46: =IF(J46>40,"High Unload Loss","Efficient") -> Efficient | N46: 14402.09 | O46: 7463.36 | P46: 21365.45 | Q46: 2057.03 | R46: 188.49
A47: =A17 -> 16.06.2026 | B47: 10.00AM | C47: C2 | D47: =N48-N47 -> 18.96 | E47: =O48-O47 -> 4.06 | F47: =P48-P47 -> 23.01 | G47: =+Q48-Q47 -> 0 | H47: =R48-R47 -> 0 | I47: =(D47/F47)*100 -> 82.398957 | J47: =(E47/F47)*100 -> 17.644502 | K47: =(F47/(F47+G47+H47)*100) -> 100 | L47: =(H47/(F47+G47+H47))*100 -> 0 | M47: =IF(J47>40,"High Unload Loss","Efficient") -> Efficient | N47: 14420.26 | O47: 7468.2 | P47: 21888.47 | Q47: 2057.03 | R47: 188.49
...

Sheet load&unload
A1: Date | B1: Time | C1: COMPRESSOR | D1: LOAD % | E1: UNLOAD% | F1: TOTAL % | H1: COMPRESSOR | I1: LOAD% | J1: UNLOAD% | K1: TOTAL% | L1: COMPREESOR | M1: LOAD% | N1: UNLOAD% | O1: TOTAL% | P1: COMPRESSOR | Q1: LOAD% | R1: UNLOAD% | S1: TOTAL%
A2: 01.06.2026 | B2: 0.41666667 | C2: C1 | D2: ='compressor readings'!I2 -> 99.457882 | E2: ='compressor readings'!J2 -> 0.54211843 | F2: =D2+E2 -> 100 | H2: C2 | I2: ='compressor readings'!I32 -> 89.943074 | J2: ='compressor readings'!J32 -> 10.009488 | K2: =I2+J2 -> 99.952562 | L2: C3 | M2: ='compressor readings'!I63 -> 80.685204 | N2: ='compressor readings'!J63 -> 19.215492 | O2: =M2+N2 -> 99.900695 | P2: C4 | Q2: 98.173346 | R2: ='compressor readings'!J94 -> 1.4134276 | S2: =Q2+R2 -> 99.586773
A3: 02.06.2026 | B3: 0.41666667 | C3: C1 | D3: ='compressor readings'!I3 -> 99.357877 | E3: ='compressor readings'!J3 -> 0.55650685 | F3: =D3+E3 -> 99.914384 | H3: C2 | I3: ='compressor readings'!I33 -> 65.960265 | J3: ='compressor readings'!J33 -> 7.5496689 | K3: =I3+J3 -> 73.509934 | L3: C3 | M3: ='compressor readings'!I64 -> 82.727273 | N3: ='compressor readings'!J64 -> 15.358852 | O3: =M3+N3 -> 98.086124 | P3: C4 | Q3: ='compressor readings'!I95 -> 93.198992 | R3: ='compressor readings'!J95 -> 1.7632242 | S3: =Q3+R3 -> 94.962217
A4: 03.06.2026 | B4: 0.41666667 | C4: C1 | D4: ='compressor readings'!I4 -> 97.155172 | E4: ='compressor readings'!J4 -> 0.38793103 | F4: =D4+E4 -> 97.543103 | H4: C2 | I4: ='compressor readings'!I34 -> 120.14324 | J4: ='compressor readings'!J34 -> 6.7144136 | K4: =I4+J4 -> 126.85765 | L4: C3 | M4: ='compressor readings'!I65 -> 84.193841 | N4: ='compressor readings'!J65 -> 17.617754 | O4: =M4+N4 -> 101.81159 | P4: C4 | Q4: ='compressor readings'!I96 -> 98.878505 | R4: ='compressor readings'!J96 -> 3.6137072 | S4: =Q4+R4 -> 102.49221
A5: 04.06.2026 | B5: 0.41666667 | C5: C1 | D5: ='compressor readings'!I5 -> 97.579425 | E5: ='compressor readings'!J5 -> 0.40342915 | F5: =D5+E5 -> 97.982854 | H5: C2 | I5: ='compressor readings'!I35 -> 90.37037 | J5: ='compressor readings'!J35 -> 9.6296296 | K5: =I5+J5 -> 100 | L5: C3 | M5: ='compressor readings'!I66 -> 83.979686 | N5: ='compressor readings'!J66 -> 14.173592 | O5: =M5+N5 -> 98.153278 | P5: C4 | Q5: ='compressor readings'!I97 -> 99.178307 | R5: ='compressor readings'!J97 -> 0.82169269 | S5: =Q5+R5 -> 100
A6: 05.06.2026 | B6: 0.41666667 | C6: C1 | D6: ='compressor readings'!I6 -> 53.064411 | E6: ='compressor readings'!J6 -> 46.933171 | F6: =D6+E6 -> 99.997582 | H6: C2 | I6: ='compressor readings'!I36 -> 65.670027 | J6: ='compressor readings'!J36 -> 34.329927 | K6: =I6+J6 -> 99.999954 | L6: C3 | M6: ='compressor readings'!I67 -> 66.205767 | N6: ='compressor readings'!J67 -> 33.790668 | O6: =M6+N6 -> 99.996435 | P6: C4 | Q6: ='compressor readings'!I98 -> 62.342056 | R6: ='compressor readings'!J98 -> 37.657944 | S6: =Q6+R6 -> 100
A7: 06.06.2026 | B7: 0.41666667 | C7: C1 | D7: ='compressor readings'!I7 -> 0 | E7: ='compressor readings'!J7 -> 0 | F7: =D7+E7 -> 0 | H7: C2 | I7: ='compressor readings'!I37 -> 0 | J7: ='compressor readings'!J37 -> 0 | K7: =I7+J7 -> 0 | L7: C3 | M7: ='compressor readings'!I68 -> 0 | N7: ='compressor readings'!J68 -> 0 | O7: =M7+N7 -> 0 | P7: C4 | Q7: ='compressor readings'!I99 -> 0 | R7: ='compressor readings'!J99 -> 0 | S7: =Q7+R7 -> 0
A8: 07.06.2026 | B8: 0.41666667 | C8: C1 | D8: ='compressor readings'!I8 -> 0 | E8: ='compressor readings'!J8 -> 0 | F8: =D8+E8 -> 0 | H8: C2 | I8: ='compressor readings'!I38 -> 0 | J8: ='compressor readings'!J38 -> 0 | K8: =I8+J8 -> 0 | L8: C3 | M8: ='compressor readings'!I69 -> 0 | N8: ='compressor readings'!J69 -> 0 | O8: =M8+N8 -> 0 | P8: C4 | Q8: ='compressor readings'!I100 -> 0 | R8: ='compressor readings'!J100 -> 0 | S8: =Q8+R8 -> 0
A9: 08.06.2026 | B9: 0.41666667 | C9: C1 | D9: ='compressor readings'!I9 -> 93.851886 | E9: ='compressor readings'!J9 -> 4.2850489 | F9: =D9+E9 -> 98.136935 | H9: C2 | I9: ='compressor readings'!I39 -> 82.685185 | J9: ='compressor readings'!J39 -> 15.324074 | K9: =I9+J9 -> 98.009259 | L9: C3 | M9: ='compressor readings'!I70 -> 66.387727 | N9: ='compressor readings'!J70 -> 31.752673 | O9: =M9+N9 -> 98.1404 | P9: C4 | Q9: ='compressor readings'!I101 -> 101.72637 | R9: ='compressor readings'!J101 -> 0 | S9: =Q9+R9 -> 101.72637
A10: 09.06.2026 | B10: 0.41666667 | C10: C1 | D10: ='compressor readings'!I10 -> 94.328922 | E10: ='compressor readings'!J10 -> 5.6710775 | F10: =D10+E10 -> 100 | H10: C2 | I10: ='compressor readings'!I40 -> 80.280456 | J10: ='compressor readings'!J40 -> 19.807187 | K10: =I10+J10 -> 100.08764 | L10: C3 | M10: ='compressor readings'!I71 -> 79.38234 | N10: ='compressor readings'!J71 -> 20.61766 | O10: =M10+N10 -> 100 | P10: C4 | Q10: ='compressor readings'!I102 -> 95.742471 | R10: ='compressor readings'!J102 -> 0.10384216 | S10: =Q10+R10 -> 95.846314
A11: 10.06.2026 | B11: 0.41666667 | C11: C1 | D11: ='compressor readings'!I11 -> 97.90146 | E11: ='compressor readings'!J11 -> 3.5538321 | F11: =D11+E11 -> 101.45529 | H11: C2 | I11: ='compressor readings'!I41 -> 83.659218 | J11: ='compressor readings'!J41 -> 16.340782 | K11: =I11+J11 -> 100 | L11: C3 | M11: ='compressor readings'!I72 -> 70.248668 | N11: ='compressor readings'!J72 -> 31.527531 | O11: =M11+N11 -> 101.7762 | P11: C4 | Q11: ='compressor readings'!I103 -> 101.65465 | R11: ='compressor readings'!J103 -> 0 | S11: =Q11+R11 -> 101.65465
A12: 11.06.2026 | B12: 0.41666667 | C12: C1 | D12: ='compressor readings'!I12 -> 94.638695 | E12: ='compressor readings'!J12 -> 5.7389277 | F12: =D12+E12 -> 100.37762 | H12: C2 | I12: ='compressor readings'!I42 -> 80.602716 | J12: ='compressor readings'!J42 -> 19.397284 | K12: =I12+J12 -> 100 | L12: C3 | M12: ='compressor readings'!I73 -> 15.68 | N12: ='compressor readings'!J73 -> 31.107206 | O12: =M12+N12 -> 46.787206 | P12: C4 | Q12: ='compressor readings'!I104 -> 98.196115 | R12: ='compressor readings'!J104 -> 0 | S12: =Q12+R12 -> 98.196115
A13: 12.06.2026 | B13: 0.41666667 | C13: C1 | D13: ='compressor readings'!I13 -> 53.164827 | E13: ='compressor readings'!J13 -> 46.835173 | F13: =D13+E13 -> 100 | H13: C2 | I13: ='compressor readings'!I43 -> 65.79583 | J13: ='compressor readings'!J43 -> 34.202335 | K13: =I13+J13 -> 99.998165 | L13: C3 | M13: ='compressor readings'!I74 -> 66.324798 | N13: ='compressor readings'!J74 -> 33.675202 | O13: =M13+N13 -> 100 | P13: C4 | Q13: ='compressor readings'!I105 -> 62.422504 | R13: ='compressor readings'!J105 -> 37.576708 | S13: =Q13+R13 -> 99.999213
A14: 13.06.2026 | C14: C1 | D14: ='compressor readings'!I14 -> 0 | E14: ='compressor readings'!J14 -> 0 | F14: =D14+E14 -> 0 | H14: C2 | I14: ='compressor readings'!I44 -> 0 | J14: ='compressor readings'!J44 -> 0 | K14: =I14+J14 -> 0 | L14: C3 | M14: ='compressor readings'!I75 -> 0 | N14: ='compressor readings'!J75 -> 0 | O14: =M14+N14 -> 0 | P14: C4 | Q14: ='compressor readings'!I106 -> 0 | R14: ='compressor readings'!J106 -> 0 | S14: =Q14+R14 -> 0
A15: 14.06.2026 | C15: C1 | D15: ='compressor readings'!I15 -> 0 | E15: ='compressor readings'!J15 -> 0 | F15: =D15+E15 -> 0 | H15: C2 | I15: ='compressor readings'!I45 -> 0 | J15: ='compressor readings'!J45 -> 0 | K15: =I15+J15 -> 0 | L15: C3 | M15: ='compressor readings'!I76 -> 0 | N15: ='compressor readings'!J76 -> 0 | O15: =M15+N15 -> 0 | P15: C4 | Q15: ='compressor readings'!I107 -> 0 | R15: ='compressor readings'!J107 -> 0 | S15: =Q15+R15 -> 0
A16: 15.06.2026 | B16: 10.00.00 | C16: C1 | D16: ='compressor readings'!I16 -> 92.507205 | E16: ='compressor readings'!J16 -> 6.5321806 | F16: =D16+E16 -> 99.039385 | H16: C2 | I16: ='compressor readings'!I46 -> 3.4740545 | J16: ='compressor readings'!J46 -> 0.92539482 | K16: =I16+J16 -> 4.3994494 | L16: C3 | M16: ='compressor readings'!I77 -> 71.280277 | N16: ='compressor readings'!J77 -> 12.802768 | O16: =M16+N16 -> 84.083045 | P16: C4 | Q16: ='compressor readings'!I108 -> 1.7276623 | R16: ='compressor readings'!J108 -> 0 | S16: =Q16+R16 -> 1.7276623
A17: 16.06.2026 | B17: 10.00.00 | C17: C1 | D17: ='compressor readings'!I17 -> 94.20904 | E17: ='compressor readings'!J17 -> 7.6741996 | F17: =D17+E17 -> 101.88324 | H17: C2 | I17: ='compressor readings'!I47 -> 82.398957 | J17: ='compressor readings'!J47 -> 17.644502 | K17: =I17+J17 -> 100.04346 | L17: C3 | M17: ='compressor readings'!I78 -> 88.469602 | N17: ='compressor readings'!J78 -> 10.020964 | O17: =M17+N17 -> 98.490566 | P17: C4
A18: 17.06.2026 | B18: 10.00.00 | C18: C1 | D18: ='compressor readings'!I18 -> 94.686453 | E18: ='compressor readings'!J18 -> 5.3135472 | F18: =D18+E18 -> 100 | H18: C2 | I18: ='compressor readings'!I48 -> 82.778702 | J18: ='compressor readings'!J48 -> 13.851913 | K18: =I18+J18 -> 96.630616 | L18: C3 | M18: ='compressor readings'!I79 -> 80.366057 | N18: ='compressor readings'!J79 -> 19.467554 | O18: =M18+N18 -> 99.833611 | P18: C4 | Q18: ='compressor readings'!I110 -> 100 | R18: ='compressor readings'!J110 -> 0 | S18: =Q18+R18 -> 100
A19: 18.06.2026 | B19: 10.00.00 | C19: C1 | D19: ='compressor readings'!I19 -> 95.291902 | E19: ='compressor readings'!J19 -> 4.7080979 | F19: =D19+E19 -> 100 | H19: C2 | I19: ='compressor readings'!I49 -> 83.317844 | J19: ='compressor readings'!J49 -> 18.355019 | K19: =I19+J19 -> 101.67286 | L19: C3 | M19: ='compressor readings'!I80 -> 89.135066 | N19: ='compressor readings'!J80 -> 12.569237 | O19: =M19+N19 -> 101.7043 | P19: C4 | R19: ='compressor readings'!J111 -> #DIV/0!
A20: 19.06.2026 | B20: 10.00.00 | C20: C1 | D20: ='compressor readings'!I20 -> 53.254182 | E20: ='compressor readings'!J20 -> 46.745818 | F20: =D20+E20 -> 100 | H20: C2 | I20: ='compressor readings'!I50 -> 65.933523 | J20: ='compressor readings'!J50 -> 34.064428 | K20: =I20+J20 -> 99.997951 | L20: C3 | M20: ='compressor readings'!I81 -> 66.484216 | N20: ='compressor readings'!J81 -> 33.515784 | O20: =M20+N20 -> 100 | P20: C4 | Q20: ='compressor readings'!I112 -> 62.473428 | R20: ='compressor readings'!J112 -> 37.52726 | S20: =Q20+R20 -> 100.00069
A21: 20.06.2026 | C21: C1 | D21: ='compressor readings'!I21 -> 0 | E21: ='compressor readings'!J21 -> 0 | F21: =D21+E21 -> 0 | H21: C2 | I21: ='compressor readings'!I51 -> 0 | J21: ='compressor readings'!J51 -> 0 | K21: =I21+J21 -> 0 | L21: C3 | M21: ='compressor readings'!I82 -> 0 | N21: ='compressor readings'!J82 -> 0 | O21: =M21+N21 -> 0 | P21: C4 | Q21: ='compressor readings'!I113 -> 0 | R21: ='compressor readings'!J113 -> 0 | S21: =Q21+R21 -> 0
A22: 21.06.2026 | C22: C1 | D22: ='compressor readings'!I22 -> 0 | E22: ='compressor readings'!J22 -> 0 | F22: =D22+E22 -> 0 | H22: C2 | I22: ='compressor readings'!I52 -> 0 | J22: ='compressor readings'!J52 -> 0 | K22: =I22+J22 -> 0 | L22: C3 | M22: ='compressor readings'!I83 -> 0 | N22: ='compressor readings'!J83 -> 0 | O22: =M22+N22 -> 0 | P22: C4 | Q22: ='compressor readings'!I114 -> 0 | R22: ='compressor readings'!J114 -> 0 | S22: =Q22+R22 -> 0
A23: 22.06.2026 | B23: 10.00.00 | C23: C1 | D23: ='compressor readings'!I23 -> 53.284091 | E23: ='compressor readings'!J23 -> 4.6715565 | F23: =D23+E23 -> 57.955648 | H23: C2 | I23: ='compressor readings'!I53 -> 658.98659 | J23: ='compressor readings'!J53 -> 339.78542 | L23: C3 | M23: ='compressor readings'!I84 -> 66.518223 | N23: ='compressor readings'!J84 -> 33.478318 | O23: =M23+N23 -> 99.996541 | P23: C4 | Q23: ='compressor readings'!I115 -> 62.476957 | R23: ='compressor readings'!J115 -> 37.522257 | S23: =Q23+R23 -> 99.999214
B31: Time
A32: =A2 -> 01.06.2026 | B32: =B2 -> 0.41666667
A33: =A3 -> 02.06.2026 | B33: =B3 -> 0.41666667
A34: 03.06.26 | B34: 10.00AM
A35: 04.06.2026 | B35: 10.00AM
A36: =A6 -> 05.06.2026 | B36: 10.00AM
A37: =A7 -> 06.06.2026 | B37: 10.00AM
A38: =A8 -> 07.06.2026 | B38: 10.00AM
A39: =A9 -> 08.06.2026 | B39: 10.00AM
A40: =A10 -> 09.06.2026 | B40: 10.00AM
A41: =A11 -> 10.06.2026 | B41: 10.00AM
A42: =A12 -> 11.06.2026 | B42: 10.00AM
A43: =A13 -> 12.06.2026 | B43: 10.00AM
A44: =A14 -> 13.06.2026
A45: =A15 -> 14.06.2026
A46: =A16 -> 15.06.2026 | B46: 10.00AM
A47: =A17 -> 16.06.2026 | B47: 10.00AM
...

Sheet contribution of each compressor
A1: Date | B1: Time | C1: TOTAL% | D1: C1% | E1: C2% | F1: C3% | G1: C4%
A2: 01.06.2026 | B2: 0.41666667 | C2: =D2+E2+F2+G2 -> 100 | D2: ='compressor readings'!N124 -> 48.709758 | E2: ='compressor readings'!O124 -> 16.084179 | F2: ='compressor readings'!P124 -> 23.831893 | G2: ='compressor readings'!Q124 -> 11.37417
A3: 02.06.2026 | B3: 0.41666667 | C3: =D3+E3+F3+G3 -> 100 | D3: ='compressor readings'!N125 -> 45.996388 | E3: ='compressor readings'!O125 -> 22.621915 | F3: ='compressor readings'!P125 -> 23.961469 | G3: ='compressor readings'!Q125 -> 7.4202288
A4: 03.06.2026 | B4: 0.41666667 | C4: =D4+E4+F4+G4 -> 100 | D4: ='compressor readings'!N126 -> 43.018368 | E4: ='compressor readings'!O126 -> 18.892306 | F4: ='compressor readings'!P126 -> 23.643597 | G4: ='compressor readings'!Q126 -> 14.44573
A5: 04.06.2026 | B5: 0.41666667 | C5: =D5+E5+F5+G5 -> 100 | D5: ='compressor readings'!N127 -> 42.068875 | E5: ='compressor readings'!O127 -> 18.529005 | F5: ='compressor readings'!P127 -> 26.535853 | G5: ='compressor readings'!Q127 -> 12.866267
A6: 05.06.2026 | B6: 0.41666667 | C6: =D6+E6+F6+G6 -> 100 | D6: ='compressor readings'!N128 -> 41.39003 | E6: ='compressor readings'!O128 -> 4.7145687 | F6: ='compressor readings'!P128 -> 46.651002 | G6: ='compressor readings'!Q128 -> 7.2443986
A7: 06.06.2026 | B7: 0.41666667 | C7: =D7+E7+F7+G7 -> 0 | D7: ='compressor readings'!N129 -> 0 | E7: ='compressor readings'!O129 -> 0 | F7: ='compressor readings'!P129 -> 0 | G7: ='compressor readings'!Q129 -> 0
A8: 07.06.2026 | B8: 0.41666667 | C8: =D8+E8+F8+G8 -> 0 | D8: ='compressor readings'!N130 -> 0 | E8: ='compressor readings'!O130 -> 0 | F8: ='compressor readings'!P130 -> 0 | G8: ='compressor readings'!Q130 -> 0
A9: 08.06.2026 | B9: 0.41666667 | C9: =D9+E9+F9+G9 -> 100 | D9: ='compressor readings'!N131 -> 39.69167 | E9: ='compressor readings'!O131 -> 17.877894 | F9: ='compressor readings'!P131 -> 20.788928 | G9: ='compressor readings'!Q131 -> 21.641508
A10: 09.06.2026 | B10: 0.41666667 | C10: =D10+E10+F10+G10 -> 100 | D10: ='compressor readings'!N132 -> 43.027927 | E10: ='compressor readings'!O132 -> 20.192553 | F10: ='compressor readings'!P132 -> 27.257077 | G10: ='compressor readings'!Q132 -> 9.5224433
A11: 10.06.2026 | B11: 0.41666667 | C11: =D11+E11+F11+G11 -> 100 | D11: ='compressor readings'!N133 -> 40.19759 | E11: ='compressor readings'!O133 -> 16.067044 | F11: ='compressor readings'!P133 -> 21.98618 | G11: ='compressor readings'!Q133 -> 21.749186
A12: 11.06.2026 | B12: 0.41666667 | C12: =D12+E12+F12+G12 -> 100 | D12: ='compressor readings'!N134 -> 40.710391 | E12: ='compressor readings'!O134 -> 17.061164 | F12: ='compressor readings'!P134 -> 22.254974 | G12: ='compressor readings'!Q134 -> 19.973471
A13: 12.06.2026 | B13: 0.41666667 | C13: =D13+E13+F13+G13 -> 100 | D13: ='compressor readings'!N135 -> 41.361919 | E13: ='compressor readings'!O135 -> 5.1730383 | F13: ='compressor readings'!P135 -> 45.904842 | G13: ='compressor readings'!Q135 -> 7.5602009
A14: 13.06.2026 | C14: =D14+E14+F14+G14 -> 0 | D14: ='compressor readings'!N136 -> 0 | E14: ='compressor readings'!O136 -> 0 | F14: ='compressor readings'!P136 -> 0 | G14: ='compressor readings'!Q136 -> 0
A15: 14.06.2026 | C15: =D15+E15+F15+G15 -> 0 | D15: ='compressor readings'!N137 -> 0 | E15: ='compressor readings'!O137 -> 0 | F15: ='compressor readings'!P137 -> 0 | G15: ='compressor readings'!Q137 -> 0
A16: 15.06.2026 | B16: 10.00.00 | C16: =D16+E16+F16+G16 -> 100 | D16: ='compressor readings'!N138 -> 45.783601 | E16: ='compressor readings'!O138 -> 21.56932 | F16: ='compressor readings'!P138 -> 32.629423 | G16: ='compressor readings'!Q138 -> 0.017656614
A17: 16.06.2026 | B17: 10.00.00 | C17: =D17+E17+F17+G17 -> 100 | D17: ='compressor readings'!N139 -> 45.927849 | E17: ='compressor readings'!O139 -> 22.062039 | F17: ='compressor readings'!P139 -> 32.010112 | G17: ='compressor readings'!Q139 -> 0
A18: 17.06.2026 | B18: 10.00.00 | C18: =D18+E18+F18+G18 -> 100 | D18: ='compressor readings'!N140 -> 43.449343 | E18: ='compressor readings'!O140 -> 21.602845 | F18: ='compressor readings'!P140 -> 29.600606 | G18: ='compressor readings'!Q140 -> 5.3472062
A19: 18.06.2026 | B19: 10.00.00 | C19: =D19+E19+F19+G19 -> 100 | D19: ='compressor readings'!N141 -> 46.057112 | E19: ='compressor readings'!O141 -> 21.863727 | F19: ='compressor readings'!P141 -> 31.388018 | G19: ='compressor readings'!Q141 -> 0.69114325
A20: 19.06.2026 | B20: 10.00.00 | C20: =D20+E20+F20+G20 -> 100 | D20: ='compressor readings'!N142 -> 41.394304 | E20: ='compressor readings'!O142 -> 5.6192564 | F20: ='compressor readings'!P142 -> 45.380711 | G20: ='compressor readings'!Q142 -> 7.6057283
A21: 20.06.2026 | C21: =D21+E21+F21+G21 -> 0 | D21: ='compressor readings'!N143 -> 0 | E21: ='compressor readings'!O143 -> 0 | F21: ='compressor readings'!P143 -> 0 | G21: ='compressor readings'!Q143 -> 0
A22: 21.06.2026 | C22: =D22+E22+F22+G22 -> 0 | D22: ='compressor readings'!N144 -> 0 | E22: ='compressor readings'!O144 -> 0 | F22: ='compressor readings'!P144 -> 0 | G22: ='compressor readings'!Q144 -> 0
A23: 22.06.2026 | B23: 10.00.00 | C23: =D23+E23+F23+G23 -> 100 | D23: ='compressor readings'!N145 -> 41.418716 | E23: ='compressor readings'!O145 -> 5.7488809 | F23: ='compressor readings'!P145 -> 45.275916 | G23: ='compressor readings'!Q145 -> 7.5564864
B31: Time
A32: =A2 -> 01.06.2026 | B32: =B2 -> 0.41666667
A33: =A3 -> 02.06.2026 | B33: =B3 -> 0.41666667
A34: 03.06.26 | B34: 10.00AM
A35: 04.06.2026 | B35: 10.00AM
A36: =A6 -> 05.06.2026 | B36: 10.00AM
A37: =A7 -> 06.06.2026 | B37: 10.00AM
A38: =A8 -> 07.06.2026 | B38: 10.00AM
A39: =A9 -> 08.06.2026 | B39: 10.00AM
A40: =A10 -> 09.06.2026 | B40: 10.00AM
A41: =A11 -> 10.06.2026 | B41: 10.00AM
A42: =A12 -> 11.06.2026 | B42: 10.00AM
A43: =A13 -> 12.06.2026 | B43: 10.00AM
A44: =A14 -> 13.06.2026
A45: =A15 -> 14.06.2026
A46: =A16 -> 15.06.2026 | B46: 10.00AM
A47: =A17 -> 16.06.2026 | B47: 10.00AM
...

Sheet MV1
A1: Date | B1: Time | C1: MV PANEL 1 CUMMLAIVE | D1: MV PANEL 2 CUMMULATIVE | E1: SR FURNANCE CMMULATIVE | F1: CPS CUMMULATIVE | G1: OVEN CUMMULATIVE | H1: AMF CUMMULATIVE | I1: MV PANEL 1 | J1: MV PANEL 2 | K1: SR FUNANCE | L1: CPS | M1: OVEN | N1: AMF | O1: TOTAL | P1: MV PANEL 2% | Q1: SR FUNANCE% | R1: CPS% | S1: OVEN% | T1: AMF% | U1: TOTAL%
A2: 01.06.2026 | B2: 0.41666667 | C2: 6065070.3 | D2: 4617859.8 | E2: 189789.43 | F2: 2870522 | G2: 6388.87 | H2: 7324.4 | I2: =C3-C2 -> 8744.09 | J2: =D3-D2 -> 7324.36 | K2: =E3-E2 -> 2723.19 | L2: =F3-F2 -> 3269.92 | M2: =G3-G2 -> 0 | N2: =H3-H2 -> 7.4 | O2: =J2+K2+L2+M2+N2 -> 13324.87 | P2: =J2/O2*100 -> 54.967591 | Q2: =K2/O2*100 -> 20.436897 | R2: =L2/O2*100 -> 24.539977 | S2: =M2/O2*100 -> 0 | T2: =N2/O2*100 -> 0.055535251 | U2: =P2+Q2+R2+S2+T2 -> 100
A3: 02.06.2026 | B3: 0.41666667 | C3: 6073814.4 | D3: 4625184.2 | E3: 192512.62 | F3: 2873791.9 | G3: 6388.87 | H3: 7331.8 | I3: =C4-C3 -> 8538.21 | J3: =D4-D3 -> 7455.87 | K3: =E4-E3 -> 2485.54 | L3: =F4-F3 -> 3350.64 | M3: =G4-G3 -> 0 | N3: =H4-H3 -> 7.61 | O3: =J3+K3+L3+M3+N3 -> 13299.66 | P3: =J3/O3*100 -> 56.060606 | Q3: =K3/O3*100 -> 18.688748 | R3: =L3/O3*100 -> 25.193426 | S3: =M3/O3*100 -> 0 | T3: =N3/O3*100 -> 0.057219508 | U3: =P3+Q3+R3+S3+T3 -> 100
A4: 03.06.2026 | B4: 0.41666667 | C4: 6082352.7 | D4: 4632640 | E4: 194998.16 | F4: 2877142.5 | G4: 6388.87 | H4: 7339.41 | I4: =C5-C4 -> -6082352.7 | J4: =D5-D4 -> -4632640 | K4: =E5-E4 -> -194998.16 | L4: =F5-F4 -> -2877142.5 | M4: =G5-G4 -> -6388.87 | N4: =H5-H4 -> -7339.41 | O4: =J4+K4+L4+M4+N4 -> -7718509 | P4: =J4/O4*100 -> 60.019882 | Q4: =K4/O4*100 -> 2.5263708 | R4: =L4/O4*100 -> 37.275885 | S4: =M4/O4*100 -> 0.08277337 | T4: =N4/O4*100 -> 0.095088442 | U4: =P4+Q4+R4+S4+T4 -> 100
A5: 04.06.2026 | B5: 0.41666667
A6: 05.06.2026 | B6: 0.41666667 | C6: 6094945.7 | D6: 4643837.8 | E6: 198134.98 | F6: 2881981.6 | G6: 6388.87 | H6: 7350.78 | I6: =C7-C6 -> -6094945.7 | J6: =D7-D6 -> -4643837.8 | K6: =E7-E6 -> -198134.98 | L6: =F7-F6 -> -2881981.6 | M6: =G7-G6 -> -6388.87 | N6: =H7-H6 -> -7350.78 | O6: =J6+K6+L6+M6+N6 -> -7737693.9 | P6: =J6/O6*100 -> 60.015785 | Q6: =K6/O6*100 -> 2.5606464 | R6: =L6/O6*100 -> 37.246001 | S6: =M6/O6*100 -> 0.08256814 | T6: =N6/O6*100 -> 0.094999622 | U6: =P6+Q6+R6+S6+T6 -> 100
A7: 06.06.2026 | B7: 0.41666667
A8: 07.06.2026 | B8: 0.41666667 | C8: 6111594 | D8: 46600072 | E8: 201563.89 | F8: 2888651.8 | G8: 6388.87 | H8: 7367.36 | I8: =C9-C8 -> 7383.36 | J8: =D9-D8 -> -41940000 | K8: =E9-E8 -> 0 | L8: =F9-F8 -> -2600000 | M8: =G9-G8 -> 0 | N8: =H9-H8 -> 0 | O8: =J8+K8+L8+M8+N8 -> -44540000 | P8: =J8/O8*100 -> 94.16255 | Q8: =K8/O8*100 -> 0 | R8: =L8/O8*100 -> 5.8374495 | S8: =M8/O8*100 -> 0 | T8: =N8/O8*100 -> 0 | U8: =P8+Q8+R8+S8+T8 -> 100
A9: 08.06.2026 | B9: 0.41666667 | C9: 6118977.3 | D9: 4660072.6 | E9: 201563.89 | F9: 288651.76 | G9: 6388.87 | H9: 7367.36 | I9: =C10-C9 -> 7558.06 | J9: =D10-D9 -> 14778.23 | K9: =E10-E9 -> 2795.79 | L9: =F10-F9 -> 2606223.3 | M9: =G10-G9 -> 0 | N9: =H10-H9 -> 15.04 | O9: =J9+K9+L9+M9+N9 -> 2623812.4 | P9: =J9/O9*100 -> 0.56323502 | Q9: =K9/O9*100 -> 0.10655449 | R9: =L9/O9*100 -> 99.329637 | S9: =M9/O9*100 -> 0 | T9: =N9/O9*100 -> 0.00057321172 | U9: =P9+Q9+R9+S9+T9 -> 100
A10: 09.06.2026 | B10: 0.41666667 | C10: 6126535.4 | D10: 4674850.9 | E10: 204359.68 | F10: 2894875.1 | G10: 6388.87 | H10: 7382.4 | I10: =C11-C10 -> 8000.46 | J10: =D11-D10 -> 7869.73 | K10: =E11-E10 -> 1574.65 | L10: =F11-F10 -> 3149.87 | M10: =G11-G10 -> 0 | N10: =H11-H10 -> 8.03 | O10: =J10+K10+L10+M10+N10 -> 12602.28 | P10: =J10/O10*100 -> 62.446875 | Q10: =K10/O10*100 -> 12.494961 | R10: =L10/O10*100 -> 24.994445 | S10: =M10/O10*100 -> 0 | T10: =N10/O10*100 -> 0.063718629 | U10: =P10+Q10+R10+S10+T10 -> 100
A11: 10.06.2026 | B11: 0.41666667 | C11: 6134535.8 | D11: 4682720.6 | E11: 205934.33 | F11: 2898024.9 | G11: 6388.87 | H11: 7390.43 | I11: =C12-C11 -> 7325.99 | J11: =D12-D11 -> 7281.31 | K11: =E12-E11 -> 1334.63 | L11: =F12-F11 -> 3169.88 | M11: =G12-G11 -> 0 | N11: =H12-H11 -> 7.43 | O11: =J11+K11+L11+M11+N11 -> 11793.25 | P11: =J11/O11*100 -> 61.741335 | Q11: =K11/O11*100 -> 11.316897 | R11: =L11/O11*100 -> 26.878765 | S11: =M11/O11*100 -> 0 | T11: =N11/O11*100 -> 0.063002141 | U11: =P11+Q11+R11+S11+T11 -> 100
A12: 11.06.2026 | B12: 0.41666667 | C12: 6141861.8 | D12: 4690001.9 | E12: 207268.96 | F12: 2901194.8 | G12: 6388.87 | H12: 7397.86 | I12: =C13-C12 -> -6141861.8 | J12: =D13-D12 -> -4690001.9 | K12: =E13-E12 -> -207268.96 | L12: =F13-F12 -> -2901194.8 | M12: =G13-G12 -> -6388.87 | N12: =H13-H12 -> -7397.86 | O12: =J12+K12+L12+M12+N12 -> -7812252.4 | P12: =J12/O12*100 -> 60.033927 | Q12: =K12/O12*100 -> 2.6531268 | R12: =L12/O12*100 -> 37.136471 | S12: =M12/O12*100 -> 0.081780128 | T12: =N12/O12*100 -> 0.094695609 | U12: =P12+Q12+R12+S12+T12 -> 100
A13: 12.06.2026 | B13: 0.41666667
A14: 13.06.2026 | C14: 6158900.5 | D14: 4706036.2 | E14: 211436.85 | F14: 2907734.7 | G14: 6388.87 | H14: 7414.27 | I14: =C15-C14 -> 7721.53 | J14: =D15-D14 -> 6567.88 | K14: =E15-E14 -> 1969.77 | L14: =F15-F14 -> 3198.61 | M14: =G15-G14 -> 0 | N14: =H15-H14 -> 6.74 | O14: =J14+K14+L14+M14+N14 -> 11743 | P14: =J14/O14*100 -> 55.930171 | Q14: =K14/O14*100 -> 16.773993 | R14: =L14/O14*100 -> 27.23844 | S14: =M14/O14*100 -> 0 | T14: =N14/O14*100 -> 0.057395895 | U14: =P14+Q14+R14+S14+T14 -> 100
A15: 14.06.2026 | C15: 6166622 | D15: 4712604.1 | E15: 213406.62 | F15: 2910933.3 | G15: 6388.87 | H15: 7421.01 | I15: =C16-C15 -> 8211.85 | J15: =D16-D15 -> 7250.43 | K15: =E16-E15 -> 2001.29 | L15: =F16-F15 -> 3315.69 | M15: =G16-G15 -> 0 | N15: =H16-H15 -> 7.42 | O15: =J15+K15+L15+M15+N15 -> 12574.83 | P15: =J15/O15*100 -> 57.658275 | Q15: =K15/O15*100 -> 15.915046 | R15: =L15/O15*100 -> 26.367673 | S15: =M15/O15*100 -> 0 | T15: =N15/O15*100 -> 0.059006762 | U15: =P15+Q15+R15+S15+T15 -> 100
A16: 15.06.2026 | B16: 10.00.00 | C16: 6174833.8 | D16: 4719854.5 | E16: 215407.91 | F16: 2914249 | G16: 6388.87 | H16: 7428.43 | I16: =C17-C16 -> 8013.51 | J16: =D17-D16 -> 6946.66 | K16: =E17-E16 -> 2413.71 | L16: =F17-F16 -> 3225.35 | M16: =G17-G16 -> 0 | N16: =H17-H16 -> 7.1 | O16: =J16+K16+L16+M16+N16 -> 12592.82 | P16: =J16/O16*100 -> 55.163657 | Q16: =K16/O16*100 -> 19.167351 | R16: =L16/O16*100 -> 25.612611 | S16: =M16/O16*100 -> 0 | T16: =N16/O16*100 -> 0.056381335 | U16: =P16+Q16+R16+S16+T16 -> 100
A17: 16.06.2026 | B17: 10.00.00 | C17: 6182847.3 | D17: 4726801.2 | E17: 217821.62 | F17: 2917474.4 | G17: 6388.87 | H17: 7435.53 | I17: =C18-C17 -> 7610.19 | J17: =D18-D17 -> 6815.86 | K17: =E18-E17 -> 1670.07 | L17: =F18-F17 -> 3419.14 | M17: =G18-G17 -> 0 | N17: =H18-H17 -> 6.91 | O17: =J17+K17+L17+M17+N17 -> 11911.98 | P17: =J17/O17*100 -> 57.218531 | Q17: =K17/O17*100 -> 14.020087 | R17: =L17/O17*100 -> 28.703373 | S17: =M17/O17*100 -> 0 | T17: =N17/O17*100 -> 0.058008828 | U17: =P17+Q17+R17+S17+T17 -> 100
A18: 17.06.2026 | B18: 10.00.00 | C18: 6190457.5 | D18: 4733617 | E18: 219491.69 | F18: 2920893.5 | G18: 6388.87 | H18: 7442.44 | I18: =C19-C18 -> -6190457.5 | J18: =D19-D18 -> -4733617 | K18: =E19-E18 -> -219491.69 | L18: =F19-F18 -> -2920893.5 | M18: =G19-G18 -> -6388.87 | N18: =H19-H18 -> -7442.44 | O18: =J18+K18+L18+M18+N18 -> -7887833.6 | P18: =J18/O18*100 -> 60.011624 | Q18: =K18/O18*100 -> 2.7826613 | R18: =L18/O18*100 -> 37.030365 | S18: =M18/O18*100 -> 0.080996511 | T18: =N18/O18*100 -> 0.094353411 | U18: =P18+Q18+R18+S18+T18 -> 100
A19: 18.06.2026 | B19: 10.00.00
A20: 19.06.2026 | B20: 10.00.00 | C20: 6207011.8 | D20: 4749077.7 | E20: 223190.87 | F20: 2928483.2 | G20: 6388.87 | H20: 7458.26 | I20: =C21-C20 -> -6207011.8 | J20: =D21-D20 -> -4749077.7 | K20: =E21-E20 -> -223190.87 | L20: =F21-F20 -> -2928483.2 | M20: =G21-G20 -> -6388.87 | N20: =H21-H20 -> -7458.26 | O20: =J20+K20+L20+M20+N20 -> -7914598.9 | P20: =J20/O20*100 -> 60.004023 | Q20: =K20/O20*100 -> 2.8199896 | R20: =L20/O20*100 -> 37.001031 | S20: =M20/O20*100 -> 0.0807226 | T20: =N20/O20*100 -> 0.094234213 | U20: =P20+Q20+R20+S20+T20 -> 100
A21: 20.06.2026 | I21: =C22-C21 -> 0 | J21: =D22-D21 -> 0 | K21: =E22-E21 -> 0 | L21: =F22-F21 -> 0 | M21: =G22-G21 -> 0 | N21: =H22-H21 -> 0 | O21: =J21+K21+L21+M21+N21 -> 0 | P21: =J21/O21*100 -> #DIV/0! | Q21: =K21/O21*100 -> #DIV/0! | R21: =L21/O21*100 -> #DIV/0! | S21: =M21/O21*100 -> #DIV/0! | T21: =N21/O21*100 -> #DIV/0! | U21: =P21+Q21+R21+S21+T21 -> #DIV/0!
A22: 21.06.2026 | I22: =C23-C22 -> 0 | J22: =D23-D22 -> 0 | K22: =E23-E22 -> 0 | L22: =F23-F22 -> 0 | M22: =G23-G22 -> 0 | N22: =H23-H22 -> 0 | O22: =J22+K22+L22+M22+N22 -> 0 | P22: =J22/O22*100 -> #DIV/0! | Q22: =K22/O22*100 -> #DIV/0! | R22: =L22/O22*100 -> #DIV/0! | S22: =M22/O22*100 -> #DIV/0! | T22: =N22/O22*100 -> #DIV/0! | U22: =P22+Q22+R22+S22+T22 -> #DIV/0!
A23: 22.06.2026 | B23: 10.00.00 | I23: =C24-C23 -> 0 | J23: =D24-D23 -> 0 | K23: =E24-E23 -> 0 | L23: =F24-F23 -> 0 | M23: =G24-G23 -> 0 | N23: =H24-H23 -> 0 | O23: =J23+K23+L23+M23+N23 -> 0 | P23: =J23/O23*100 -> #DIV/0! | Q23: =K23/O23*100 -> #DIV/0! | R23: =L23/O23*100 -> #DIV/0! | S23: =M23/O23*100 -> #DIV/0! | T23: =N23/O23*100 -> #DIV/0! | U23: =P23+Q23+R23+S23+T23 -> #DIV/0!
I24: =C25-C24 -> 0 | J24: =D25-D24 -> 0 | K24: =E25-E24 -> 0 | L24: =F25-F24 -> 0 | M24: =G25-G24 -> 0 | N24: =H25-H24 -> 0 | O24: =J24+K24+L24+M24+N24 -> 0 | P24: =J24/O24*100 -> #DIV/0! | Q24: =K24/O24*100 -> #DIV/0! | R24: =L24/O24*100 -> #DIV/0! | S24: =M24/O24*100 -> #DIV/0! | T24: =N24/O24*100 -> #DIV/0! | U24: =P24+Q24+R24+S24+T24 -> #DIV/0!
I25: =C26-C25 -> 0 | J25: =D26-D25 -> 0 | K25: =E26-E25 -> 0 | L25: =F26-F25 -> 0 | M25: =G26-G25 -> 0 | N25: =H26-H25 -> 0 | O25: =J25+K25+L25+M25+N25 -> 0 | P25: =J25/O25*100 -> #DIV/0! | Q25: =K25/O25*100 -> #DIV/0! | R25: =L25/O25*100 -> #DIV/0! | S25: =M25/O25*100 -> #DIV/0! | T25: =N25/O25*100 -> #DIV/0! | U25: =P25+Q25+R25+S25+T25 -> #DIV/0!
N26: =H27-H26 -> 0
N27: =H28-H27 -> 0
N28: =H29-H28 -> 0

Sheet MV 2
A1: Date | B1: Time | C1: MV PANEL 2 CUMMULATIVE | D1: SSB1 CUMMULATIVE | E1: SSB2 CUMMULATIVE | F1: SSB3 CUMMULATIVE | G1: SSB4 CUMMULATIVE | H1: SSB5 CUMMULATIVE | I1: COMPRESSOR CUMMULATIVE | J1: MLSB CUMMULATIVE | K1: MV PANEL 2 | L1: SSB1 | M1: SSB2 | N1: SSB3 | O1: SSB4 | P1: SSB5 | Q1: COMPRESSSOR | R1: MLSB | S1: SSB1% | T1: SSB2% | U1: SSB3% | V1: SSB4% | W1: SSB5% | X1: COMPR% | Y1: MLSB% | Z1: TOTAL | AA1: TOTAL%
A2: 01.06.2026 | B2: 0.41666667 | C2: 4617859.8 | D2: 726565.46 | E2: 1700973.4 | F2: 456149.05 | G2: 511647.09 | H2: 128768.94 | I2: 47980.78 | J2: 44179.309 | K2: =C3-C2 -> 7324.36 | L2: =D3-D2 -> 600.7 | M2: =E3-E2 -> 1656.68 | N2: =F3-F2 -> 537.11 | O2: =G3-G2 -> 653.57 | P2: =H3-H2 -> 174.63 | Q2: =I3-I2 -> 39870.35 | R2: =J3-J2 -> 185.371 | S2: =L2/Z2*100 -> 1.375279 | T2: =M2/Z2*100 -> 3.7929035 | U2: =N2/Z2*100 -> 1.2296922 | V2: =O2/Z2*100 -> 1.4963227 | W2: =P2/Z2*100 -> 0.3998085 | X2: =Q2/Z2*100 -> 91.281594 | Y2: =R2/Z2*100 -> 0.4243996 | Z2: =L2+M2+N2+O2+P2+Q2+R2 -> 43678.411 | AA2: =S2+T2+U2+V2+W2+X2+Y2 -> 100
A3: 02.06.2026 | B3: 0.41666667 | C3: 4625184.2 | D3: 727166.16 | E3: 1702630.1 | F3: 456686.16 | G3: 512300.66 | H3: 128943.57 | I3: 87851.13 | J3: 44364.68 | K3: =C4-C3 -> 7455.87 | L3: =D4-D3 -> 656.52 | M3: =E4-E3 -> 1626.486 | N3: =F4-F3 -> 444.8 | O3: =G4-G3 -> 628.57 | P3: =H4-H3 -> 1162140.5 | Q3: =I4-I3 -> 2691.62 | R3: =J4-J3 -> 197.09 | S3: =L3/Z3*100 -> 0.056190352 | T3: =M3/Z3*100 -> 0.13920798 | U3: =N3/Z3*100 -> 0.038069623 | V3: =O3/Z3*100 -> 0.053798163 | W3: =P3/Z3*100 -> 99.465494 | X3: =Q3/Z3*100 -> 0.23037086 | Y3: =R3/Z3*100 -> 0.016868575 | Z3: =L3+M3+N3+O3+P3+Q3+R3 -> 1168385.6 | AA3: =S3+T3+U3+V3+W3+X3+Y3 -> 100
A4: 03.06.2026 | B4: 0.41666667 | C4: 4632640 | D4: 727822.68 | E4: 1704256.5 | F4: 457130.96 | G4: 512929.23 | H4: 1291084.1 | I4: 90542.75 | J4: 44561.77 | K4: =C5-C4 -> -4632640 | L4: =D5-D4 -> -727822.68 | M4: =E5-E4 -> -1704256.5 | N4: =F5-F4 -> -457130.96 | O4: =G5-G4 -> -512929.23 | P4: =H5-H4 -> -1291084.1 | Q4: =I5-I4 -> -90542.75 | R4: =J5-J4 -> -44561.77 | S4: =L4/Z4*100 -> 15.074011 | T4: =M4/Z4*100 -> 35.297033 | U4: =N4/Z4*100 -> 9.4676865 | V4: =O4/Z4*100 -> 10.62333 | W4: =P4/Z4*100 -> 26.739776 | X4: =Q4/Z4*100 -> 1.8752402 | Y4: =R4/Z4*100 -> 0.92292342 | Z4: =L4+M4+N4+O4+P4+Q4+R4 -> -4828328 | AA4: =S4+T4+U4+V4+W4+X4+Y4 -> 100
A5: 04.06.2026 | B5: 0.41666667
A6: 05.06.2026 | B6: 0.41666667 | C6: 4643837.8 | D6: 728985.17 | E6: 1706357 | F6: 458064.18 | G6: 514104.51 | H6: 1294472.3 | I6: 95861.93 | J6: 44927.97 | K6: =C7-C6 -> -4643837.8 | L6: =D7-D6 -> -728985.17 | M6: =E7-E6 -> -1706357 | N6: =F7-F6 -> -458064.18 | O6: =G7-G6 -> -514104.51 | P6: =H7-H6 -> -1294472.3 | Q6: =I7-I6 -> -95861.93 | R6: =J7-J6 -> -44927.97 | S6: =L6/Z6*100 -> 15.053052 | T6: =M6/Z6*100 -> 35.235122 | U6: =N6/Z6*100 -> 9.4587166 | V6: =O6/Z6*100 -> 10.615912 | W6: =P6/Z6*100 -> 26.729981 | X6: =Q6/Z6*100 -> 1.9794842 | Y6: =R6/Z6*100 -> 0.9277323 | Z6: =L6+M6+N6+O6+P6+Q6+R6 -> -4842773.1 | AA6: =S6+T6+U6+V6+W6+X6+Y6 -> 100
A7: 06.06.2026 | B7: 0.41666667
A8: 07.06.2026 | B8: 0.41666667 | C8: 4660072.6 | D8: 730396.61 | E8: 1709078.2 | F8: 459118.6 | G8: 515978.45 | H8: 1298375.7 | I8: 102955.5 | J8: 45352.35 | K8: =C9-C8 -> 7420.96 | L8: =D9-D8 -> 632.13 | M8: =E9-E8 -> 7269.58 | N8: =F9-F8 -> 501.45 | O8: =G9-G8 -> 646.62 | P8: =H9-H8 -> 1633.26 | Q8: =I9-I8 -> 1878.06 | R8: =J9-J8 -> 200.64 | S8: =L8/Z8*100 -> 4.9533214 | T8: =M8/Z8*100 -> 56.963862 | U8: =N8/Z8*100 -> 3.9293231 | V8: =O8/Z8*100 -> 5.0668639 | W8: =P8/Z8*100 -> 12.798098 | X8: =Q8/Z8*100 -> 14.716332 | Y8: =R8/Z8*100 -> 1.5721994 | Z8: =L8+M8+N8+O8+P8+Q8+R8 -> 12761.74 | AA8: =S8+T8+U8+V8+W8+X8+Y8 -> 100
A9: 08.06.2026 | B9: 0.41666667 | C9: 4667493.6 | D9: 731028.74 | E9: 1716347.8 | F9: 459620.05 | G9: 516625.07 | H9: 1300009 | I9: 104833.56 | J9: 45552.99 | K9: =C10-C9 -> 7356.57 | L9: =D10-D9 -> 630.73 | M9: =E10-E9 -> -1544735.8 | N9: =F10-F9 -> 440.85 | O9: =G10-G9 -> 634.7 | P9: =H10-H9 -> 1910.83 | Q9: =I10-I9 -> 2467.12 | R9: =J10-J9 -> 218.76 | S9: =L9/Z9*100 -> -0.040998215 | T9: =M9/Z9*100 -> 100.4097 | U9: =N9/Z9*100 -> -0.028655784 | V9: =O9/Z9*100 -> -0.041256269 | W9: =P9/Z9*100 -> -0.12420627 | X9: =Q9/Z9*100 -> -0.16036579 | Y9: =R9/Z9*100 -> -0.014219665 | Z9: =L9+M9+N9+O9+P9+Q9+R9 -> -1538432.8 | AA9: =S9+T9+U9+V9+W9+X9+Y9 -> 100
A10: 09.06.2026 | B10: 0.41666667 | C10: 4674850.2 | D10: 731659.47 | E10: 171611.92 | F10: 460060.9 | G10: 517259.77 | H10: 1301919.8 | I10: 107300.68 | J10: 45771.75 | K10: =C11-C10 -> 7870.43 | L10: =D11-D10 -> 874.3 | M10: =E11-E10 -> 1541417.1 | N10: =F11-F10 -> 525.9 | O10: =G11-G10 -> 690.65 | P10: =H11-H10 -> 1850.12 | Q10: =I11-I10 -> 2896.82 | R10: =J11-J10 -> 207.73 | S10: =L10/Z10*100 -> 0.056462455 | T10: =M10/Z10*100 -> 99.544999 | U10: =N10/Z10*100 -> 0.033962719 | V10: =O10/Z10*100 -> 0.044602304 | W10: =P10/Z10*100 -> 0.11948109 | X10: =Q10/Z10*100 -> 0.18707717 | Y10: =R10/Z10*100 -> 0.013415242 | Z10: =L10+M10+N10+O10+P10+Q10+R10 -> 1548462.6 | AA10: =S10+T10+U10+V10+W10+X10+Y10 -> 100
A11: 10.06.2026 | B11: 0.41666667 | C11: 4682720.6 | D11: 732533.77 | E11: 1713029 | F11: 460586.8 | G11: 517950.42 | H11: 1303769.9 | I11: 110197.5 | J11: 45979.48 | K11: =C12-C11 -> 7281.31 | L11: =D12-D11 -> 688.44 | M11: =E12-E11 -> 1369.553 | N11: =F12-F11 -> 496.68 | O11: =G12-G11 -> 685.56 | P11: =H12-H11 -> 1518.5 | Q11: =I12-I11 -> 2813.67 | R11: =J12-J11 -> 186.97 | S11: =L11/Z11*100 -> 8.8723664 | T11: =M11/Z11*100 -> 17.650305 | U11: =N11/Z11*100 -> 6.4010327 | V11: =O11/Z11*100 -> 8.83525 | W11: =P11/Z11*100 -> 19.56988 | X11: =Q11/Z11*100 -> 36.261564 | Y11: =R11/Z11*100 -> 2.4096019 | Z11: =L11+M11+N11+O11+P11+Q11+R11 -> 7759.373 | AA11: =S11+T11+U11+V11+W11+X11+Y11 -> 100
A12: 11.06.2026 | B12: 0.41666667 | C12: 4690001.9 | D12: 733222.21 | E12: 1714398.6 | F12: 461083.48 | G12: 518635.98 | H12: 1305288.4 | I12: 113011.17 | J12: 46166.45 | K12: =C13-C12 -> -4690001.9 | L12: =D13-D12 -> -733222.21 | M12: =E13-E12 -> -1714398.6 | N12: =F13-F12 -> -461083.48 | O12: =G13-G12 -> -518635.98 | P12: =H13-H12 -> -1305288.4 | Q12: =I13-I12 -> -113011.17 | R12: =J13-J12 -> -46166.45 | S12: =L12/Z12*100 -> 14.988783 | T12: =M12/Z12*100 -> 35.046329 | U12: =N12/Z12*100 -> 9.4256283 | V12: =O12/Z12*100 -> 10.602136 | W12: =P12/Z12*100 -> 26.683159 | X12: =Q12/Z12*100 -> 2.3102135 | Y12: =R12/Z12*100 -> 0.94375058 | Z12: =L12+M12+N12+O12+P12+Q12+R12 -> -4891806.3 | AA12: =S12+T12+U12+V12+W12+X12+Y12 -> 100
A13: 12.06.2026 | B13: 0.41666667
A14: 13.06.2026 | C14: 4706036.2 | D14: 724123.32 | E14: 1717244.5 | F14: 462242.31 | G14: 526531.09 | H14: 1309320.2 | I14: 119277.81 | J14: 46619.81 | K14: =C15-C14 -> 6567.88 | L14: =D15-D14 -> 11285.74 | M14: =E15-E14 -> 1425.99 | N14: =F15-F14 -> 479.8 | O14: =G15-G14 -> -5059.3 | P14: =H15-H14 -> 1638.92 | Q14: =I15-I14 -> 2070.87 | R14: =J15-J14 -> 198.55 | S14: =L14/Z14*100 -> 93.730945 | T14: =M14/Z14*100 -> 11.84321 | U14: =N14/Z14*100 -> 3.9848612 | V14: =O14/Z14*100 -> -42.018775 | W14: =P14/Z14*100 -> 13.611648 | X14: =Q14/Z14*100 -> 17.199103 | Y14: =R14/Z14*100 -> 1.6490083 | Z14: =L14+M14+N14+O14+P14+Q14+R14 -> 12040.57 | AA14: =S14+T14+U14+V14+W14+X14+Y14 -> 100
A15: 14.06.2026 | C15: 4712604.1 | D15: 735409.06 | E15: 1718670.5 | F15: 462722.11 | G15: 521471.79 | H15: 1310959.1 | I15: 121348.68 | J15: 46818.36 | K15: =C16-C15 -> 7250.43 | L15: =D16-D15 -> 651.63 | M15: =E16-E15 -> 1524.88 | N15: =F16-F15 -> 559.78 | O15: =G16-G15 -> 659.92 | P15: =H16-H15 -> -1177939.3 | Q15: =I16-I15 -> 2160.73 | R15: =J16-J15 -> 218.95 | S15: =L15/Z15*100 -> -0.055592079 | T15: =M15/Z15*100 -> -0.13009108 | U15: =N15/Z15*100 -> -0.047756141 | V15: =O15/Z15*100 -> -0.056299318 | W15: =P15/Z15*100 -> 100.49275 | X15: =Q15/Z15*100 -> -0.18433693 | Y15: =R15/Z15*100 -> -0.018679137 | Z15: =L15+M15+N15+O15+P15+Q15+R15 -> -1172163.4 | AA15: =S15+T15+U15+V15+W15+X15+Y15 -> 100
A16: 15.06.2026 | B16: 10.00.00 | C16: 4719854.5 | D16: 736060.69 | E16: 1720195.4 | F16: 463281.89 | G16: 522131.71 | H16: 133019.82 | I16: 123509.41 | J16: 47037.31 | K16: =C17-C16 -> 6946.66 | L16: =D17-D16 -> 612.45 | M16: =E17-E16 -> 1501.3 | N16: =F17-F16 -> 555.03 | O16: =G17-G16 -> 595.74 | P16: =H17-H16 -> 1181626.7 | Q16: =I17-I16 -> 2302.01 | R16: =J17-J16 -> -42312.377 | S16: =L16/Z16*100 -> 0.053494651 | T16: =M16/Z16*100 -> 0.13113155 | U16: =N16/Z16*100 -> 0.048479282 | V16: =O16/Z16*100 -> 0.05203511 | W16: =P16/Z16*100 -> 103.20958 | X16: =Q16/Z16*100 -> 0.20106984 | Y16: =R16/Z16*100 -> -3.6957888 | Z16: =L16+M16+N16+O16+P16+Q16+R16 -> 1144880.8 | AA16: =S16+T16+U16+V16+W16+X16+Y16 -> 100
A17: 16.06.2026 | B17: 10.00.00 | C17: 4726801.2 | D17: 736673.14 | E17: 1721696.6 | F17: 463836.92 | G17: 522727.45 | H17: 1314646.5 | I17: 125811.42 | J17: 4724.933 | K17: =C18-C17 -> 6815.91 | L17: =D18-D17 -> 647.02 | M17: =E18-E17 -> 1969.16 | N17: =F18-F17 -> 505.63 | O17: =G18-G17 -> 585.03 | P17: =H18-H17 -> 1464.53 | Q17: =I18-I17 -> 1132205 | R17: =J18-J17 -> 42761.507 | S17: =L17/Z17*100 -> 0.054825795 | T17: =M17/Z17*100 -> 0.16685846 | U17: =N17/Z17*100 -> 0.042844992 | V17: =O17/Z17*100 -> 0.04957302 | W17: =P17/Z17*100 -> 0.12409821 | X17: =Q17/Z17*100 -> 95.938366 | Y17: =R17/Z17*100 -> 3.623433 | Z17: =L17+M17+N17+O17+P17+Q17+R17 -> 1180137.9 | AA17: =S17+T17+U17+V17+W17+X17+Y17 -> 100
A18: 17.06.2026 | B18: 10.00.00 | C18: 4733617.1 | D18: 737320.16 | E18: 1723665.8 | F18: 464342.55 | G18: 523312.48 | H18: 1316111 | I18: 1258016.5 | J18: 47486.44 | K18: =C19-C18 -> -4733617.1 | L18: =D19-D18 -> -737320.16 | M18: =E19-E18 -> -1723665.8 | N18: =F19-F18 -> -464342.55 | O18: =G19-G18 -> -523312.48 | P18: =H19-H18 -> -1316111 | Q18: =I19-I18 -> -1258016.5 | R18: =J19-J18 -> -47486.44 | S18: =L18/Z18*100 -> 12.146445 | T18: =M18/Z18*100 -> 28.395279 | U18: =N18/Z18*100 -> 7.6494736 | V18: =O18/Z18*100 -> 8.6209309 | W18: =P18/Z18*100 -> 21.681314 | X18: =Q18/Z18*100 -> 20.724277 | Y18: =R18/Z18*100 -> 0.78228082 | Z18: =L18+M18+N18+O18+P18+Q18+R18 -> -6070254.9 | AA18: =S18+T18+U18+V18+W18+X18+Y18 -> 100
A19: 18.06.2026 | B19: 10.00.00
A20: 19.06.2026 | B20: 10.00.00 | C20: 4749077.7 | D20: 738732.12 | E20: 1726185.4 | F20: 465626.36 | G20: 525076.41 | H20: 1320022.1 | I20: 133019.88 | J20: 47980.78 | K20: =C21-C20 -> -4749077.7 | L20: =D21-D20 -> -738732.12 | M20: =E21-E20 -> -1726185.4 | N20: =F21-F20 -> -465626.36 | O20: =G21-G20 -> -525076.41 | P20: =H21-H20 -> -1320022.1 | Q20: =I21-I20 -> -133019.88 | R20: =J21-J20 -> -47980.78 | S20: =L20/Z20*100 -> 14.90388 | T20: =M20/Z20*100 -> 34.825696 | U20: =N20/Z20*100 -> 9.393986 | V20: =O20/Z20*100 -> 10.593388 | W20: =P20/Z20*100 -> 26.631373 | X20: =Q20/Z20*100 -> 2.6836687 | Y20: =R20/Z20*100 -> 0.96800958 | Z20: =L20+M20+N20+O20+P20+Q20+R20 -> -4956643.1 | AA20: =S20+T20+U20+V20+W20+X20+Y20 -> 100
A21: 20.06.2026
A22: 21.06.2026
A23: 22.06.2026 | B23: 10.00.00
B31: Time
A32: =A2 -> 01.06.2026 | B32: =B2 -> 0.41666667
A33: =A3 -> 02.06.2026 | B33: =B3 -> 0.41666667
A34: 03.06.26 | B34: 10.00AM
A35: 04.06.2026 | B35: 10.00AM
A36: =A6 -> 05.06.2026 | B36: 10.00AM
A37: =A7 -> 06.06.2026 | B37: 10.00AM
A38: =A8 -> 07.06.2026 | B38: 10.00AM
A39: =A9 -> 08.06.2026 | B39: 10.00AM
A40: =A10 -> 09.06.2026 | B40: 10.00AM
A41: =A11 -> 10.06.2026 | B41: 10.00AM
A42: =A12 -> 11.06.2026 | B42: 10.00AM
A43: =A13 -> 12.06.2026 | B43: 10.00AM
A44: =A14 -> 13.06.2026
A45: =A15 -> 14.06.2026
A46: =A16 -> 15.06.2026 | B46: 10.00AM
A47: =A17 -> 16.06.2026 | B47: 10.00AM
...

Sheet COMPRESSORINMV PANEL1
A1: Date | B1: Time | C1: COMPREEESOR% | D1: C1% | E1: C2% | F1: C3% | G1: C4% | H1: TOTAL%
A2: 01.06.2026 | B2: 0.41666667 | C2: ='compressor readings'!M124/'MV1'!I2*100 -> 36.51838 | D2: ='compressor readings'!I124/'MV1'!I2*100 -> 17.788015 | E2: ='compressor readings'!J124/'MV1'!I2*100 -> 5.8736815 | F2: ='compressor readings'!K124/'MV1'!I2*100 -> 8.7030211 | G2: ='compressor readings'!L124/'MV1'!I2*100 -> 4.1536626 | H2: =D2+E2+F2+G2 -> 36.51838
A3: 02.06.2026 | B3: 0.41666667 | C3: ='compressor readings'!M125/'MV1'!I3*100 -> 38.907452 | D3: ='compressor readings'!I125/'MV1'!I3*100 -> 17.896023 | E3: ='compressor readings'!J125/'MV1'!I3*100 -> 8.8016106 | F3: ='compressor readings'!K125/'MV1'!I3*100 -> 9.3227972 | G3: ='compressor readings'!L125/'MV1'!I3*100 -> 2.887022 | H3: =D3+E3+F3+G3 -> 38.907452
A4: 03.06.2026 | B4: 0.41666667 | C4: ='compressor readings'!M128/'MV1'!I6*100 -> 10.497253 | D4: ='compressor readings'!I128/'MV1'!I6*100 -> 4.3448164 | E4: ='compressor readings'!J128/'MV1'!I6*100 -> 0.49490022 | F4: ='compressor readings'!K128/'MV1'!I6*100 -> 4.897074 | G4: ='compressor readings'!L128/'MV1'!I6*100 -> 0.76046288 | H4: =D4+E4+F4+G4 -> 10.497253
A5: 04.06.2026 | B5: 0.41666667 | C5: ='compressor readings'!M131/'MV1'!I9*100 -> 45.314538 | D5: ='compressor readings'!I131/'MV1'!I9*100 -> 17.986097 | E5: ='compressor readings'!J131/'MV1'!I9*100 -> 8.1012853 | F5: ='compressor readings'!K131/'MV1'!I9*100 -> 9.4204068 | G5: ='compressor readings'!L131/'MV1'!I9*100 -> 9.8067494 | H5: =D5+E5+F5+G5 -> 45.314538
A6: 05.06.2026 | B6: 0.41666667 | C6: ='compressor readings'!M132/'MV1'!I10*100 -> 39.207746 | D6: ='compressor readings'!I132/'MV1'!I10*100 -> 16.87028 | E6: ='compressor readings'!J132/'MV1'!I10*100 -> 7.9170448 | F6: ='compressor readings'!K132/'MV1'!I10*100 -> 10.686886 | G6: ='compressor readings'!L132/'MV1'!I10*100 -> 3.7335353 | H6: =D6+E6+F6+G6 -> 39.207746
A7: 06.06.2026 | B7: 0.41666667 | C7: ='compressor readings'!M133/'MV1'!I11*100 -> 47.805143 | D7: ='compressor readings'!I133/'MV1'!I11*100 -> 19.216515 | E7: ='compressor readings'!J133/'MV1'!I11*100 -> 7.6808732 | F7: ='compressor readings'!K133/'MV1'!I11*100 -> 10.510525 | G7: ='compressor readings'!L133/'MV1'!I11*100 -> 10.39723 | H7: =D7+E7+F7+G7 -> 47.805143
A8: 07.06.2026 | B8: 0.41666667 | C8: ='compressor readings'!M138/'MV1'!I16*100 -> 35.337823 | D8: ='compressor readings'!I138/'MV1'!I16*100 -> 16.178928 | E8: ='compressor readings'!J138/'MV1'!I16*100 -> 7.6221281 | F8: ='compressor readings'!K138/'MV1'!I16*100 -> 11.530528 | G8: ='compressor readings'!L138/'MV1'!I16*100 -> 0.0062394631 | H8: =D8+E8+F8+G8 -> 35.337823
A9: 08.06.2026 | B9: 0.41666667 | C9: ='compressor readings'!M139/'MV1'!I17*100 -> 38.464217 | D9: ='compressor readings'!I139/'MV1'!I17*100 -> 17.665788 | E9: ='compressor readings'!J139/'MV1'!I17*100 -> 8.4859905 | F9: ='compressor readings'!K139/'MV1'!I17*100 -> 12.312439 | G9: ='compressor readings'!L139/'MV1'!I17*100 -> 0 | H9: =D9+E9+F9+G9 -> 38.464217
A10: 09.06.2026 | B10: 0.41666667 | C10: ='compressor readings'!M142/'MV1'!I20*100 -> 10.949749 | D10: ='compressor readings'!I142/'MV1'!I20*100 -> 4.5325724 | E10: ='compressor readings'!J142/'MV1'!I20*100 -> 0.61529447 | F10: ='compressor readings'!K142/'MV1'!I20*100 -> 4.9690739 | G10: ='compressor readings'!L142/'MV1'!I20*100 -> 0.83280815 | H10: =D10+E10+F10+G10 -> 10.949749
A11: 10.06.2026 | B11: 0.41666667
A12: 11.06.2026 | B12: 0.41666667
A13: 12.06.2026 | B13: 0.41666667
A14: 13.06.2026
A15: 14.06.2026
A16: 15.06.2026 | B16: 10.00.00
A17: 16.06.2026 | B17: 10.00.00
A18: 17.06.2026 | B18: 10.00.00
A19: 18.06.2026 | B19: 10.00.00
A20: 19.06.2026 | B20: 10.00.00
A21: 20.06.2026
A22: 21.06.2026
A23: 22.06.2026 | B23: 10.00.00
B31: Time
A32: =A2 -> 01.06.2026 | B32: =B2 -> 0.41666667
A33: =A3 -> 02.06.2026 | B33: =B3 -> 0.41666667
A34: 03.06.26 | B34: 10.00AM
A35: 04.06.2026 | B35: 10.00AM
A36: =A6 -> 05.06.2026 | B36: 10.00AM
A37: =A7 -> 06.06.2026 | B37: 10.00AM
A38: =A8 -> 07.06.2026 | B38: 10.00AM
A39: =A9 -> 08.06.2026 | B39: 10.00AM
A40: =A10 -> 09.06.2026 | B40: 10.00AM
A41: =A11 -> 10.06.2026 | B41: 10.00AM
A42: =A12 -> 11.06.2026 | B42: 10.00AM
A43: =A13 -> 12.06.2026 | B43: 10.00AM
A44: =A14 -> 13.06.2026
A45: =A15 -> 14.06.2026
A46: =A16 -> 15.06.2026 | B46: 10.00AM
A47: =A17 -> 16.06.2026 | B47: 10.00AM
...

Sheet CFM IN EACH BAY
A1: BAY NAME | B1: APPLICATION | C1: CFM | D1: COUNT | E1: TOTAL CFM | F1: overall
A2: CPS | B2: Paint boooth /Sanding booth | C2: 8 | D2: 3 | E2: =C2*D2 -> 24
B3: Grit blasting machine [Big] | C3: 220 | D3: 1 | E3: =C3*D3 -> 220
B4: Grit blasting machine [Small-1] | C4: 210 | D4: 1 | E4: =C4*D4 -> 210
B5: Grit blasting machine [Assembly] | C5: 210 | D5: 1 | E5: =C5*D5 -> 210
B6: 2KE Paint mixing plant | C6: 8 | D6: 1 | E6: =C6*D6 -> 8 | F6: =E2+E3+E4+E5+E6+E7+E8+E9+E10 -> 732
B7: 2KS Paint mixing plant | C7: 6 | D7: 1 | E7: =C7*D7 -> 6
B8: Dust collector [12 S/v] | C8: 12 | D8: 2 | E8: =C8*D8 -> 24
B9: Dust collector [18 s/v] | C9: 20 | D9: 1 | E9: =C9*D9 -> 20
B10: spray paint gun | C10: 10 | D10: 1 | E10: =C10*D10 -> 10
B12: spares | D12: 2
B13: Dummy | C13: 14
A25: BAY 8 | B25: Welding | C25: 4 | D25: 2 | E25: =C25*D25 -> 8
B26: Pneumatic impact wrench 1/2-Inch | C26: 12 | D26: 1 | E26: =C26*D26 -> 12
B27: Laser cutting machine | C27: 8 | D27: 1 | E27: =C27*D27 -> 8
B28: 1/2 -Inch cleaning hose | C28: 22 | D28: 1 | E28: =C28*D28 -> 22
B30: Spares
B31: Dummy | D31: 5
D32: 3
A41: BAY 7 | B41: Welding | C41: 4 | D41: 1 | E41: =C41*D41 -> 4
D42: 11
B43: Dummy | D43: 1
B44: Spares
A52: BAY 5 | B52: Spares | D52: 5
B53: Dummy | D53: 5
